a3exception/__init__.py,sha256=slqP6NXRtg9Ra2uB910RMZ5r7q--fi3VkUAWn1tz9ys,47
a3exception/dynamic_error_factory.py,sha256=Q53dctXORqwu6UqTzUHeXAuOoWg0ZiuH2vQqUKow_YU,1091
a3exception/errors.py,sha256=EEYcT7o-t9Xz7Sx7XOslnXAAONW51o6P4LXm_0eKx18,2580
a3exception-0.3.0.dist-info/LICENSE,sha256=pvjMLq-SZGceLR4IdvNkr8RcwC0mUNvxTGD9NU2bkjo,1062
a3exception-0.3.0.dist-info/METADATA,sha256=ueh8flw8Q8pF9VNzHAWquK2an5x1rThOtu0IxpzGIiU,2226
a3exception-0.3.0.dist-info/WHEEL,sha256=tZoeGjtWxWRfdplE7E3d45VPlLNQnvbKiYnx7gwAy8A,92
a3exception-0.3.0.dist-info/top_level.txt,sha256=hxEYxiQIP2GargR-GEUH8aRofBscUGKUruJsSPCm7gs,12
a3exception-0.3.0.dist-info/RECORD,,
